Workbook

Sheet Master
A1: Item Master | E1: =+CONCATENATE("Dashboard ",TEXT(Use!A4,"MMMM YYYY"),"")
A3: NO | B3: ITEM | C3: NOS | E3: NO | F3: Particular | G3: Amount
A4: 1 | B4: Rice | C4: Kg | E4: 1 | F4: Total Stock Purchase | G4: =+Purchase!H1003
A5: =+A4+1 | B5: Atta | C5: Kg | E5: =+E4+1 | F5: Total Stock Used | G5: =+Use!G1865
A6: =+A5+1 | B6: Oil | C6: Liter | E6: =+E5+1 | F6: Current Stock Value | G6: =+G4-G5
A7: =+A6+1 | B7: Dal (Toor) | C7: Kg | E7: =+E6+1 | F7: Total Lunch Count | G7: =+Meal!B35
A8: =+A7+1 | B8: Salt | C8: Kg | E8: =+E7+1 | F8: Total Dinner Count | G8: =+Meal!C35
A9: =+A8+1 | B9: Mirch-P | C9: Gram | E9: =+E8+1 | F9: Cost Per Lunch | G9: =+Meal!F35
A10: =+A9+1 | B10: Haldi-P | C10: Gram | E10: =+E9+1 | F10: Cost Per Dinner | G10: =+Meal!G35
A11: =+A10+1 | B11: Jeera | C11: Gram
A12: =+A11+1 | B12: Sukha Mirch | C12: Gram
A13: =+A12+1 | B13: Tej Patta | C13: Gram
A14: =+A13+1 | B14: Akha Masala | C14: Gram
A15: =+A14+1 | B15: Rai | C15: Gram | E15: Other Expanse
A16: =+A15+1 | B16: Dhania P | C16: Gram
A17: =+A16+1 | B17: Garam Masala | C17: Gram | E17: NO | F17: Particular | G17: Amount
A18: =+A17+1 | B18: EGG | C18: Nos | E18: 1 | F18: Total Stock Used | G18: =+G5
A19: =+A18+1 | B19: FISH | C19: Kg | E19: =+E18+1 | F19: Canteen Salary | G19: 171000
A20: =+A19+1 | B20: CHICKEN | C20: Kg | E20: =+E19+1 | F20: Gas | G20: 2000
A21: =+A20+1 | B21: Aloo | C21: Kg | E21: =+E20+1 | F21: Wood | G21: 5000
A22: =+A21+1 | B22: Galka | C22: Kg | E22: =+E21+1
A23: =+A22+1 | B23: Tomato | C23: Kg | E23: =+E22+1
A24: =+A23+1 | B24: Onion | C24: Kg | E24: =+E23+1
A25: =+A24+1 | B25: Adrak | C25: Kg | E25: =+E24+1
A26: =+A25+1 | B26: Lehsun | C26: Kg | E26: =+E25+1
A27: =+A26+1 | B27: Hari Mirch | C27: Gram | E27: =+E26+1
A28: =+A27+1 | B28: MIX VEG | C28: Kg | E28: Total | G28: =SUM(G18:G27)
A29: =+A28+1 | B29: Other 2 | C29: Kg | F29: Totel Meal | G29: =+G7+G8
A30: =+A29+1 | B30: Other 3 | C30: Kg | F30: Per Meal Cost | G30: =+G28/(Meal!B35+Meal!C35)
A31: =+A30+1 | B31: Other 4 | C31: Kg
A32: =+A31+1 | B32: Other 5 | C32: Kg
A33: =+A32+1 | B33: Other 6 | C33: Kg

Sheet Purchase
A1: RCS CANTEEN PURCHASE ENTRY
A2: =TEXT(+A4,"MMMM YYYY")
A3: Date | B3: Bill No | C3: Supplier | D3: Item | E3: Qty | F3: Unit | G3: Rate | H3: Amount
A4: 46235 | B4: 1 | C4: ABC | D4: Rice | E4: 500 | F4: =IFERROR(+VLOOKUP(D4,Master!B:C,2,0),"") | G4: 55 | H4: =+E4*G4
A5: 46235 | B5: 1 | C5: ABC | D5: Atta | E5: 500 | F5: =IFERROR(+VLOOKUP(D5,Master!B:C,2,0),"") | G5: 39 | H5: =+E5*G5
A6: 46235 | B6: 1 | C6: ABC | D6: Oil | E6: 500 | F6: =IFERROR(+VLOOKUP(D6,Master!B:C,2,0),"") | G6: 120 | H6: =+E6*G6
A7: 46235 | B7: 1 | C7: ABC | D7: Dal (Toor) | E7: 500 | F7: =IFERROR(+VLOOKUP(D7,Master!B:C,2,0),"") | G7: 110 | H7: =+E7*G7
A8: 46235 | B8: 1 | C8: ABC | D8: Salt | E8: 500 | F8: =IFERROR(+VLOOKUP(D8,Master!B:C,2,0),"") | G8: 20 | H8: =+E8*G8
A9: 46235 | B9: 1 | C9: ABC | D9: Mirch-P | E9: 500 | F9: =IFERROR(+VLOOKUP(D9,Master!B:C,2,0),"") | G9: 150 | H9: =+E9*G9
A10: 46235 | B10: 1 | C10: ABC | D10: Haldi-P | E10: 500 | F10: =IFERROR(+VLOOKUP(D10,Master!B:C,2,0),"") | G10: 201 | H10: =+E10*G10
A11: 46235 | B11: 1 | C11: ABC | D11: Jeera | E11: 500 | F11: =IFERROR(+VLOOKUP(D11,Master!B:C,2,0),"") | G11: 300 | H11: =+E11*G11
A12: 46235 | B12: 1 | C12: ABC | D12: Sukha Mirch | E12: 500 | F12: =IFERROR(+VLOOKUP(D12,Master!B:C,2,0),"") | G12: 200 | H12: =+E12*G12
A13: 46235 | B13: 1 | C13: ABC | D13: Tej Patta | E13: 500 | F13: =IFERROR(+VLOOKUP(D13,Master!B:C,2,0),"") | G13: 50 | H13: =+E13*G13
A14: 46235 | B14: 1 | C14: ABC | D14: Akha Masala | E14: 500 | F14: =IFERROR(+VLOOKUP(D14,Master!B:C,2,0),"") | G14: 260 | H14: =+E14*G14
A15: 46235 | B15: 1 | C15: ABC | D15: Rai | E15: 500 | F15: =IFERROR(+VLOOKUP(D15,Master!B:C,2,0),"") | G15: 14 | H15: =+E15*G15
... A29: 46235 | B29: 1 | C29: ABC | D29: MIX VEG | E29: 500 | F29: =IFERROR(+VLOOKUP(D29,Master!B:C,2,0),"") | G29: 200 | H29: =+E29*G29
A30: 46236 | B30: 2 | C30: ABC | D30: Rice | F30: =IFERROR(+VLOOKUP(D30,Master!B:C,2,0),"") | H30: =+E30*G30
A31: 46236 | B31: 2 | C31: ABC | D31: Atta | F31: =IFERROR(+VLOOKUP(D31,Master!B:C,2,0),"") | H31: =+E31*G31
A32: 46236 | B32: 2 | C32: ABC | D32: Oil | F32: =IFERROR(+VLOOKUP(D32,Master!B:C,2,0),"") | H32: =+E32*G32
A33: 46236 | B33: 2 | C33: ABC | D33: Dal (Toor) | F33: =IFERROR(+VLOOKUP(D33,Master!B:C,2,0),"") | H33: =+E33*G33
A34: 46236 | B34: 2 | C34: ABC | D34: Salt | F34: =IFERROR(+VLOOKUP(D34,Master!B:C,2,0),"") | H34: =+E34*G34
A35: 46236 | B35: 2 | C35: ABC | D35: Mirch-P | F35: =IFERROR(+VLOOKUP(D35,Master!B:C,2,0),"") | H35: =+E35*G35
A36: 46236 | B36: 2 | C36: ABC | D36: Haldi-P | F36: =IFERROR(+VLOOKUP(D36,Master!B:C,2,0),"") | H36: =+E36*G36
A37: 46236 | B37: 2 | C37: ABC | D37: Jeera | F37: =IFERROR(+VLOOKUP(D37,Master!B:C,2,0),"") | H37: =+E37*G37
A38: 46236 | B38: 2 | C38: ABC | D38: Sukha Mirch | F38: =IFERROR(+VLOOKUP(D38,Master!B:C,2,0),"") | H38: =+E38*G38
A39: 46236 | B39: 2 | C39: ABC | D39: Tej Patta | F39: =IFERROR(+VLOOKUP(D39,Master!B:C,2,0),"") | H39: =+E39*G39
A40: 46236 | B40: 2 | C40: ABC | D40: Akha Masala | F40: =IFERROR(+VLOOKUP(D40,Master!B:C,2,0),"") | H40: =+E40*G40
A41: 46236 | B41: 2 | C41: ABC | D41: Rai | F41: =IFERROR(+VLOOKUP(D41,Master!B:C,2,0),"") | H41: =+E41*G41
... A54: 46236 | B54: 2 | C54: ABC | D54: Hari Mirch | F54: =IFERROR(+VLOOKUP(D54,Master!B:C,2,0),"") | H54: =+E54*G54
F55: =IFERROR(+VLOOKUP(D55,Master!B:C,2,0),"") | H55: =+E55*G55
F56: =IFERROR(+VLOOKUP(D56,Master!B:C,2,0),"") | H56: =+E56*G56
F57: =IFERROR(+VLOOKUP(D57,Master!B:C,2,0),"") | H57: =+E57*G57
F58: =IFERROR(+VLOOKUP(D58,Master!B:C,2,0),"") | H58: =+E58*G58
F59: =IFERROR(+VLOOKUP(D59,Master!B:C,2,0),"") | H59: =+E59*G59
F60: =IFERROR(+VLOOKUP(D60,Master!B:C,2,0),"") | H60: =+E60*G60
F61: =IFERROR(+VLOOKUP(D61,Master!B:C,2,0),"") | H61: =+E61*G61
F62: =IFERROR(+VLOOKUP(D62,Master!B:C,2,0),"") | H62: =+E62*G62
F63: =IFERROR(+VLOOKUP(D63,Master!B:C,2,0),"") | H63: =+E63*G63
F64: =IFERROR(+VLOOKUP(D64,Master!B:C,2,0),"") | H64: =+E64*G64
F65: =IFERROR(+VLOOKUP(D65,Master!B:C,2,0),"") | H65: =+E65*G65
...

Sheet Use
A1: DAILY STOCK USE ENTRY
A2: =TEXT(+A4,"MMMM YYYY")
A3: Date | B3: Meal | C3: Item | D3: Qty Used | E3: Unit | F3: Rate | G3: Amount
A4: 46235 | B4: Lunch | C4: Rice | D4: 50 | E4: =IFERROR(+VLOOKUP(C4,Master!B:C,2,0),"") | F4: =LOOKUP(2,1/((Purchase!$D$1:$D$500=C4)*(Purchase!$A$1:$A$500<=A4)),Purchase!$G$1:$G$500) | G4: =+D4*F4
A5: 46235 | B5: Lunch | C5: Atta | D5: 55 | E5: =IFERROR(+VLOOKUP(C5,Master!B:C,2,0),"") | F5: =LOOKUP(2,1/((Purchase!$D$1:$D$500=C5)*(Purchase!$A$1:$A$500<=A5)),Purchase!$G$1:$G$500) | G5: =+D5*F5
A6: 46235 | B6: Lunch | C6: Oil | D6: 8 | E6: =IFERROR(+VLOOKUP(C6,Master!B:C,2,0),"") | F6: =LOOKUP(2,1/((Purchase!$D$1:$D$500=C6)*(Purchase!$A$1:$A$500<=A6)),Purchase!$G$1:$G$500) | G6: =+D6*F6
A7: 46235 | B7: Lunch | C7: Dal (Toor) | D7: 16 | E7: =IFERROR(+VLOOKUP(C7,Master!B:C,2,0),"") | F7: =LOOKUP(2,1/((Purchase!$D$1:$D$500=C7)*(Purchase!$A$1:$A$500<=A7)),Purchase!$G$1:$G$500) | G7: =+D7*F7
A8: 46235 | B8: Lunch | C8: Salt | D8: 3 | E8: =IFERROR(+VLOOKUP(C8,Master!B:C,2,0),"") | F8: =LOOKUP(2,1/((Purchase!$D$1:$D$500=C8)*(Purchase!$A$1:$A$500<=A8)),Purchase!$G$1:$G$500) | G8: =+D8*F8
A9: 46235 | B9: Lunch | C9: Mirch-P | D9: 800 | E9: =IFERROR(+VLOOKUP(C9,Master!B:C,2,0),"") | F9: =LOOKUP(2,1/((Purchase!$D$1:$D$500=C9)*(Purchase!$A$1:$A$500<=A9)),Purchase!$G$1:$G$500) | G9: =+D9*F9
A10: 46235 | B10: Lunch | C10: Haldi-P | D10: 500 | E10: =IFERROR(+VLOOKUP(C10,Master!B:C,2,0),"") | F10: =LOOKUP(2,1/((Purchase!$D$1:$D$500=C10)*(Purchase!$A$1:$A$500<=A10)),Purchase!$G$1:$G$500) | G10: =+D10*F10
A11: 46235 | B11: Lunch | C11: Jeera | D11: 100 | E11: =IFERROR(+VLOOKUP(C11,Master!B:C,2,0),"") | F11: =LOOKUP(2,1/((Purchase!$D$1:$D$500=C11)*(Purchase!$A$1:$A$500<=A11)),Purchase!$G$1:$G$500) | G11: =+D11*F11
A12: 46235 | B12: Lunch | C12: Sukha Mirch | D12: 200 | E12: =IFERROR(+VLOOKUP(C12,Master!B:C,2,0),"") | F12: =LOOKUP(2,1/((Purchase!$D$1:$D$500=C12)*(Purchase!$A$1:$A$500<=A12)),Purchase!$G$1:$G$500) | G12: =+D12*F12
A13: 46235 | B13: Lunch | C13: Tej Patta | D13: 50 | E13: =IFERROR(+VLOOKUP(C13,Master!B:C,2,0),"") | F13: =LOOKUP(2,1/((Purchase!$D$1:$D$500=C13)*(Purchase!$A$1:$A$500<=A13)),Purchase!$G$1:$G$500) | G13: =+D13*F13
A14: 46235 | B14: Lunch | C14: Akha Masala | D14: 300 | E14: =IFERROR(+VLOOKUP(C14,Master!B:C,2,0),"") | F14: =LOOKUP(2,1/((Purchase!$D$1:$D$500=C14)*(Purchase!$A$1:$A$500<=A14)),Purchase!$G$1:$G$500) | G14: =+D14*F14
A15: 46235 | B15: Lunch | C15: Rai | D15: 100 | E15: =IFERROR(+VLOOKUP(C15,Master!B:C,2,0),"") | F15: =LOOKUP(2,1/((Purchase!$D$1:$D$500=C15)*(Purchase!$A$1:$A$500<=A15)),Purchase!$G$1:$G$500) | G15: =+D15*F15
... A27: 46235 | B27: Lunch | C27: Hari Mirch | D27: 400 | E27: =IFERROR(+VLOOKUP(C27,Master!B:C,2,0),"") | F27: =LOOKUP(2,1/((Purchase!$D$1:$D$500=C27)*(Purchase!$A$1:$A$500<=A27)),Purchase!$G$1:$G$500) | G27: =+D27*F27
A28: 46235 | B28: Lunch | E28: =IFERROR(+VLOOKUP(C28,Master!B:C,2,0),"") | F28: =LOOKUP(2,1/((Purchase!$D$1:$D$500=C28)*(Purchase!$A$1:$A$500<=A28)),Purchase!$G$1:$G$500)
A29: 46235 | B29: Dinner | C29: Rice | D29: 71 | E29: =IFERROR(+VLOOKUP(C29,Master!B:C,2,0),"") | F29: =LOOKUP(2,1/((Purchase!$D$1:$D$500=C29)*(Purchase!$A$1:$A$500<=A29)),Purchase!$G$1:$G$500) | G29: =+D29*F29
A30: 46235 | B30: Dinner | C30: Atta | D30: 65 | E30: =IFERROR(+VLOOKUP(C30,Master!B:C,2,0),"") | F30: =LOOKUP(2,1/((Purchase!$D$1:$D$500=C30)*(Purchase!$A$1:$A$500<=A30)),Purchase!$G$1:$G$500) | G30: =+D30*F30
A31: 46235 | B31: Dinner | C31: Oil | D31: 15 | E31: =IFERROR(+VLOOKUP(C31,Master!B:C,2,0),"") | F31: =LOOKUP(2,1/((Purchase!$D$1:$D$500=C31)*(Purchase!$A$1:$A$500<=A31)),Purchase!$G$1:$G$500) | G31: =+D31*F31
A32: 46235 | B32: Dinner | C32: Dal (Toor) | D32: 0 | E32: =IFERROR(+VLOOKUP(C32,Master!B:C,2,0),"") | F32: =LOOKUP(2,1/((Purchase!$D$1:$D$500=C32)*(Purchase!$A$1:$A$500<=A32)),Purchase!$G$1:$G$500) | G32: =+D32*F32
A33: 46235 | B33: Dinner | C33: Salt | D33: 3 | E33: =IFERROR(+VLOOKUP(C33,Master!B:C,2,0),"") | F33: =LOOKUP(2,1/((Purchase!$D$1:$D$500=C33)*(Purchase!$A$1:$A$500<=A33)),Purchase!$G$1:$G$500) | G33: =+D33*F33
A34: 46235 | B34: Dinner | C34: Mirch-P | D34: 1 | E34: =IFERROR(+VLOOKUP(C34,Master!B:C,2,0),"") | F34: =LOOKUP(2,1/((Purchase!$D$1:$D$500=C34)*(Purchase!$A$1:$A$500<=A34)),Purchase!$G$1:$G$500) | G34: =+D34*F34
A35: 46235 | B35: Dinner | C35: Haldi-P | D35: 500 | E35: =IFERROR(+VLOOKUP(C35,Master!B:C,2,0),"") | F35: =LOOKUP(2,1/((Purchase!$D$1:$D$500=C35)*(Purchase!$A$1:$A$500<=A35)),Purchase!$G$1:$G$500) | G35: =+D35*F35
A36: 46235 | B36: Dinner | C36: Jeera | D36: 100 | E36: =IFERROR(+VLOOKUP(C36,Master!B:C,2,0),"") | F36: =LOOKUP(2,1/((Purchase!$D$1:$D$500=C36)*(Purchase!$A$1:$A$500<=A36)),Purchase!$G$1:$G$500) | G36: =+D36*F36
A37: 46235 | B37: Dinner | C37: Sukha Mirch | D37: 200 | E37: =IFERROR(+VLOOKUP(C37,Master!B:C,2,0),"") | F37: =LOOKUP(2,1/((Purchase!$D$1:$D$500=C37)*(Purchase!$A$1:$A$500<=A37)),Purchase!$G$1:$G$500) | G37: =+D37*F37
A38: 46235 | B38: Dinner | C38: Tej Patta | D38: 50 | E38: =IFERROR(+VLOOKUP(C38,Master!B:C,2,0),"") | F38: =LOOKUP(2,1/((Purchase!$D$1:$D$500=C38)*(Purchase!$A$1:$A$500<=A38)),Purchase!$G$1:$G$500) | G38: =+D38*F38
A39: 46235 | B39: Dinner | C39: Akha Masala | D39: 400 | E39: =IFERROR(+VLOOKUP(C39,Master!B:C,2,0),"") | F39: =LOOKUP(2,1/((Purchase!$D$1:$D$500=C39)*(Purchase!$A$1:$A$500<=A39)),Purchase!$G$1:$G$500) | G39: =+D39*F39
A40: 46235 | B40: Dinner | C40: Rai | D40: 100 | E40: =IFERROR(+VLOOKUP(C40,Master!B:C,2,0),"") | F40: =LOOKUP(2,1/((Purchase!$D$1:$D$500=C40)*(Purchase!$A$1:$A$500<=A40)),Purchase!$G$1:$G$500) | G40: =+D40*F40
... A43: 46235 | B43: Dinner | C43: Garam Masala | D43: 0 | E43: =IFERROR(+VLOOKUP(C43,Master!B:C,2,0),"") | F43: =LOOKUP(2,1/((Purchase!$D$1:$D$500=C43)*(Purchase!$A$1:$A$500<=A43)),Purchase!$G$1:$G$500) | G43: =+D43*F43
A44: 46235 | B44: Dinner | C44: EGG | E44: =IFERROR(+VLOOKUP(C44,Master!B:C,2,0),"") | F44: =LOOKUP(2,1/((Purchase!$D$1:$D$500=C44)*(Purchase!$A$1:$A$500<=A44)),Purchase!$G$1:$G$500) | G44: =+D44*F44
A45: 46235 | B45: Dinner | C45: FISH | E45: =IFERROR(+VLOOKUP(C45,Master!B:C,2,0),"") | F45: =LOOKUP(2,1/((Purchase!$D$1:$D$500=C45)*(Purchase!$A$1:$A$500<=A45)),Purchase!$G$1:$G$500) | G45: =+D45*F45
A46: 46235 | B46: Dinner | C46: CHICKEN | E46: =IFERROR(+VLOOKUP(C46,Master!B:C,2,0),"") | F46: =LOOKUP(2,1/((Purchase!$D$1:$D$500=C46)*(Purchase!$A$1:$A$500<=A46)),Purchase!$G$1:$G$500) | G46: =+D46*F46
A47: 46235 | B47: Dinner | C47: Aloo | D47: 65 | E47: =IFERROR(+VLOOKUP(C47,Master!B:C,2,0),"") | F47: =LOOKUP(2,1/((Purchase!$D$1:$D$500=C47)*(Purchase!$A$1:$A$500<=A47)),Purchase!$G$1:$G$500) | G47: =+D47*F47
A48: 46235 | B48: Dinner | C48: Galka | D48: 62 | E48: =IFERROR(+VLOOKUP(C48,Master!B:C,2,0),"") | F48: =LOOKUP(2,1/((Purchase!$D$1:$D$500=C48)*(Purchase!$A$1:$A$500<=A48)),Purchase!$G$1:$G$500) | G48: =+D48*F48
A49: 46235 | B49: Dinner | C49: Tomato | D49: 5 | E49: =IFERROR(+VLOOKUP(C49,Master!B:C,2,0),"") | F49: =LOOKUP(2,1/((Purchase!$D$1:$D$500=C49)*(Purchase!$A$1:$A$500<=A49)),Purchase!$G$1:$G$500) | G49: =+D49*F49
A50: 46235 | B50: Dinner | C50: Onion | D50: 30 | E50: =IFERROR(+VLOOKUP(C50,Master!B:C,2,0),"") | F50: =LOOKUP(2,1/((Purchase!$D$1:$D$500=C50)*(Purchase!$A$1:$A$500<=A50)),Purchase!$G$1:$G$500) | G50: =+D50*F50
A51: 46235 | B51: Dinner | C51: Adrak | D51: 2 | E51: =IFERROR(+VLOOKUP(C51,Master!B:C,2,0),"") | F51: =LOOKUP(2,1/((Purchase!$D$1:$D$500=C51)*(Purchase!$A$1:$A$500<=A51)),Purchase!$G$1:$G$500) | G51: =+D51*F51
A52: 46235 | B52: Dinner | C52: Lehsun | D52: 2 | E52: =IFERROR(+VLOOKUP(C52,Master!B:C,2,0),"") | F52: =LOOKUP(2,1/((Purchase!$D$1:$D$500=C52)*(Purchase!$A$1:$A$500<=A52)),Purchase!$G$1:$G$500) | G52: =+D52*F52
A53: 46235 | B53: Dinner | C53: Hari Mirch | D53: 500 | E53: =IFERROR(+VLOOKUP(C53,Master!B:C,2,0),"") | F53: =LOOKUP(2,1/((Purchase!$D$1:$D$500=C53)*(Purchase!$A$1:$A$500<=A53)),Purchase!$G$1:$G$500) | G53: =+D53*F53
...

Sheet Meal
A1: RCS Per Meal Cost Report
A2: =TEXT(+A4,"MMMM YYYY")
A3: Date | B3: Lunch | C3: Dinner | D3: Lunch Total Cost | E3: Dinner Total Cost | F3: Cost Per Lunch | G3: Cost Per Dinner
A4: =+Use!A4 | B4: 700 | C4: 700 | D4: =+SUMIFS(Use!G:G,Use!A:A,A4,Use!B:B,$B$3) | E4: =+SUMIFS(Use!G:G,Use!A:A,A4,Use!B:B,$C$3) | F4: =IFERROR(+D4/B4,0) | G4: =+IFERROR(E4/C4,0)
A5: =+A4+1 | B5: 500 | C5: 200 | D5: =+SUMIFS(Use!G:G,Use!A:A,A5,Use!B:B,$B$3) | E5: =+SUMIFS(Use!G:G,Use!A:A,A5,Use!B:B,$C$3) | F5: =IFERROR(+D5/B5,0) | G5: =+IFERROR(E5/C5,0)
A6: =+A5+1 | D6: =+SUMIFS(Use!G:G,Use!A:A,A6,Use!B:B,$B$3) | E6: =+SUMIFS(Use!G:G,Use!A:A,A6,Use!B:B,$C$3) | F6: =IFERROR(+D6/B6,0) | G6: =+IFERROR(E6/C6,0)
A7: =+A6+1 | D7: =+SUMIFS(Use!G:G,Use!A:A,A7,Use!B:B,$B$3) | E7: =+SUMIFS(Use!G:G,Use!A:A,A7,Use!B:B,$C$3) | F7: =IFERROR(+D7/B7,0) | G7: =+IFERROR(E7/C7,0)
A8: =+A7+1 | D8: =+SUMIFS(Use!G:G,Use!A:A,A8,Use!B:B,$B$3) | E8: =+SUMIFS(Use!G:G,Use!A:A,A8,Use!B:B,$C$3) | F8: =IFERROR(+D8/B8,0) | G8: =+IFERROR(E8/C8,0)
A9: =+A8+1 | D9: =+SUMIFS(Use!G:G,Use!A:A,A9,Use!B:B,$B$3) | E9: =+SUMIFS(Use!G:G,Use!A:A,A9,Use!B:B,$C$3) | F9: =IFERROR(+D9/B9,0) | G9: =+IFERROR(E9/C9,0)
A10: =+A9+1 | D10: =+SUMIFS(Use!G:G,Use!A:A,A10,Use!B:B,$B$3) | E10: =+SUMIFS(Use!G:G,Use!A:A,A10,Use!B:B,$C$3) | F10: =IFERROR(+D10/B10,0) | G10: =+IFERROR(E10/C10,0)
A11: =+A10+1 | D11: =+SUMIFS(Use!G:G,Use!A:A,A11,Use!B:B,$B$3) | E11: =+SUMIFS(Use!G:G,Use!A:A,A11,Use!B:B,$C$3) | F11: =IFERROR(+D11/B11,0) | G11: =+IFERROR(E11/C11,0)
A12: =+A11+1 | D12: =+SUMIFS(Use!G:G,Use!A:A,A12,Use!B:B,$B$3) | E12: =+SUMIFS(Use!G:G,Use!A:A,A12,Use!B:B,$C$3) | F12: =IFERROR(+D12/B12,0) | G12: =+IFERROR(E12/C12,0)
A13: =+A12+1 | D13: =+SUMIFS(Use!G:G,Use!A:A,A13,Use!B:B,$B$3) | E13: =+SUMIFS(Use!G:G,Use!A:A,A13,Use!B:B,$C$3) | F13: =IFERROR(+D13/B13,0) | G13: =+IFERROR(E13/C13,0)
A14: =+A13+1 | D14: =+SUMIFS(Use!G:G,Use!A:A,A14,Use!B:B,$B$3) | E14: =+SUMIFS(Use!G:G,Use!A:A,A14,Use!B:B,$C$3) | F14: =IFERROR(+D14/B14,0) | G14: =+IFERROR(E14/C14,0)
A15: =+A14+1 | D15: =+SUMIFS(Use!G:G,Use!A:A,A15,Use!B:B,$B$3) | E15: =+SUMIFS(Use!G:G,Use!A:A,A15,Use!B:B,$C$3) | F15: =IFERROR(+D15/B15,0) | G15: =+IFERROR(E15/C15,0)
A16: =+A15+1 | D16: =+SUMIFS(Use!G:G,Use!A:A,A16,Use!B:B,$B$3) | E16: =+SUMIFS(Use!G:G,Use!A:A,A16,Use!B:B,$C$3) | F16: =IFERROR(+D16/B16,0) | G16: =+IFERROR(E16/C16,0)
A17: =+A16+1 | D17: =+SUMIFS(Use!G:G,Use!A:A,A17,Use!B:B,$B$3) | E17: =+SUMIFS(Use!G:G,Use!A:A,A17,Use!B:B,$C$3) | F17: =IFERROR(+D17/B17,0) | G17: =+IFERROR(E17/C17,0)
... A29: =+A28+1 | D29: =+SUMIFS(Use!G:G,Use!A:A,A29,Use!B:B,$B$3) | E29: =+SUMIFS(Use!G:G,Use!A:A,A29,Use!B:B,$C$3) | F29: =IFERROR(+D29/B29,0) | G29: =+IFERROR(E29/C29,0)
A30: =+IF((A29+1)>EOMONTH(A4,0),"",(A29+1)) | D30: =+SUMIFS(Use!G:G,Use!A:A,A30,Use!B:B,$B$3) | E30: =+SUMIFS(Use!G:G,Use!A:A,A30,Use!B:B,$C$3) | F30: =IFERROR(+D30/B30,0) | G30: =+IFERROR(E30/C30,0)
A31: =+IF((A30+1)>EOMONTH(A5,0),"",(A30+1)) | D31: =+SUMIFS(Use!G:G,Use!A:A,A31,Use!B:B,$B$3) | E31: =+SUMIFS(Use!G:G,Use!A:A,A31,Use!B:B,$C$3) | F31: =IFERROR(+D31/B31,0) | G31: =+IFERROR(E31/C31,0)
A32: =IFERROR(+IF((A31+1)>EOMONTH(A6,0),"",(A31+1)),"") | D32: =+SUMIFS(Use!G:G,Use!A:A,A32,Use!B:B,$B$3) | E32: =+SUMIFS(Use!G:G,Use!A:A,A32,Use!B:B,$C$3) | F32: =IFERROR(+D32/B32,0) | G32: =+IFERROR(E32/C32,0)
A33: =IFERROR(+IF((A32+1)>EOMONTH(A7,0),"",(A32+1)),"") | D33: =+SUMIFS(Use!G:G,Use!A:A,A33,Use!B:B,$B$3) | E33: =+SUMIFS(Use!G:G,Use!A:A,A33,Use!B:B,$C$3) | F33: =IFERROR(+D33/B33,0) | G33: =+IFERROR(E33/C33,0)
A34: =IFERROR(+IF((A33+1)>EOMONTH(A8,0),"",(A33+1)),"") | D34: =+SUMIFS(Use!G:G,Use!A:A,A34,Use!B:B,$B$3) | E34: =+SUMIFS(Use!G:G,Use!A:A,A34,Use!B:B,$C$3) | F34: =IFERROR(+D34/B34,0) | G34: =+IFERROR(E34/C34,0)
A35: Total Monthly | B35: =SUM(B4:B34) | C35: =SUM(C4:C34) | D35: =SUM(D4:D34) | E35: =SUM(E4:E34) | F35: =IFERROR(+D35/B35,0) | G35: =+IFERROR(E35/C35,0)

Sheet Stock Report
A1: TOTAL STOCK REPORT
A2: =TEXT(+Use!A4,"MMMM YYYY")
A3: Sr No | B3: Item | C3: Unit | D3: Purchased | E3: Used | F3: Closing Stock
A4: =+Master!A4 | B4: =+Master!B4 | C4: =+Master!C4 | D4: =SUMIFS(Purchase!E:E,Purchase!D:D,B4) | E4: =SUMIFS(Use!D:D,Use!C:C,B4) | F4: =+D4-E4
A5: =+Master!A5 | B5: =+Master!B5 | C5: =+Master!C5 | D5: =SUMIFS(Purchase!E:E,Purchase!D:D,B5) | E5: =SUMIFS(Use!D:D,Use!C:C,B5) | F5: =+D5-E5
A6: =+Master!A6 | B6: =+Master!B6 | C6: =+Master!C6 | D6: =SUMIFS(Purchase!E:E,Purchase!D:D,B6) | E6: =SUMIFS(Use!D:D,Use!C:C,B6) | F6: =+D6-E6
A7: =+Master!A7 | B7: =+Master!B7 | C7: =+Master!C7 | D7: =SUMIFS(Purchase!E:E,Purchase!D:D,B7) | E7: =SUMIFS(Use!D:D,Use!C:C,B7) | F7: =+D7-E7
A8: =+Master!A8 | B8: =+Master!B8 | C8: =+Master!C8 | D8: =SUMIFS(Purchase!E:E,Purchase!D:D,B8) | E8: =SUMIFS(Use!D:D,Use!C:C,B8) | F8: =+D8-E8
A9: =+Master!A9 | B9: =+Master!B9 | C9: =+Master!C9 | D9: =SUMIFS(Purchase!E:E,Purchase!D:D,B9) | E9: =SUMIFS(Use!D:D,Use!C:C,B9) | F9: =+D9-E9
A10: =+Master!A10 | B10: =+Master!B10 | C10: =+Master!C10 | D10: =SUMIFS(Purchase!E:E,Purchase!D:D,B10) | E10: =SUMIFS(Use!D:D,Use!C:C,B10) | F10: =+D10-E10
A11: =+Master!A11 | B11: =+Master!B11 | C11: =+Master!C11 | D11: =SUMIFS(Purchase!E:E,Purchase!D:D,B11) | E11: =SUMIFS(Use!D:D,Use!C:C,B11) | F11: =+D11-E11
A12: =+Master!A12 | B12: =+Master!B12 | C12: =+Master!C12 | D12: =SUMIFS(Purchase!E:E,Purchase!D:D,B12) | E12: =SUMIFS(Use!D:D,Use!C:C,B12) | F12: =+D12-E12
A13: =+Master!A13 | B13: =+Master!B13 | C13: =+Master!C13 | D13: =SUMIFS(Purchase!E:E,Purchase!D:D,B13) | E13: =SUMIFS(Use!D:D,Use!C:C,B13) | F13: =+D13-E13
A14: =+Master!A14 | B14: =+Master!B14 | C14: =+Master!C14 | D14: =SUMIFS(Purchase!E:E,Purchase!D:D,B14) | E14: =SUMIFS(Use!D:D,Use!C:C,B14) | F14: =+D14-E14
A15: =+Master!A15 | B15: =+Master!B15 | C15: =+Master!C15 | D15: =SUMIFS(Purchase!E:E,Purchase!D:D,B15) | E15: =SUMIFS(Use!D:D,Use!C:C,B15) | F15: =+D15-E15
... A33: =+Master!A33 | B33: =+Master!B33 | C33: =+Master!C33 | D33: =SUMIFS(Purchase!E:E,Purchase!D:D,B33) | E33: =SUMIFS(Use!D:D,Use!C:C,B33) | F33: =+D33-E33

Sheet Supplier Master
B2: RCS Canteen — Supplier Master
B4: No | C4: Supplier Name | D4: Category | E4: Contact Person | F4: Phone | G4: Email | H4: Address | I4: GSTIN | J4: Rating | K4: On-Time Rate | L4: Quality Score | M4: Notes | N4: Last Order Date
B5: 1 | C5: Fresh Meats | D5: Meat
B6: 2 | C6: Rajesh Grains | D6: Grains
B7: 3 | C7: Local Market | D7: Vegetables

Sheet Ingredient Master
B2: RCS Canteen — Ingredient Master
B4: No | C4: Ingredient | D4: Unit | E4: Category | F4: Current Stock | G4: Min Stock | H4: Last Purchase Price | I4: Avg Cost | J4: Supplier
B5: 1 | C5: Hari Mirch | D5: kg | E5: Vegetables | F5: 2 | G5: 40 | H5: 38 | I5: 38 | J5: Local Market
B6: 2 | C6: Aloo | D6: kg | E6: Vegetables | F6: 15 | G6: 20 | H6: 22 | I6: 22 | J6: Local Market
B7: 3 | C7: Adrak | D7: kg | E7: Vegetables | F7: 2 | G7: 60 | H7: 55 | I7: 55 | J7: Local Market
B8: 4 | C8: EGG | D8: pcs | E8: Dairy | F8: 100 | G8: 7 | H8: 6.5 | I8: 6.5
B9: 5 | C9: Haldi-P | D9: kg | E9: Spices | F9: 1 | G9: 400 | H9: 380 | I9: 380
B10: 6 | C10: Mirch-P | D10: kg | E10: Spices | F10: 1 | G10: 350 | H10: 340 | I10: 340
B11: 7 | C11: Galka | D11: kg | E11: Vegetables | F11: 5 | G11: 25 | H11: 23 | I11: 23 | J11: Local Market
B12: 8 | C12: Onion | D12: kg | E12: Vegetables | F12: 10 | G12: 25 | H12: 28 | I12: 28 | J12: Local Market
B13: 9 | C13: Salt | D13: kg | E13: Spices | F13: 5 | G13: 10 | H13: 10 | I13: 10
B14: 10 | C14: Tej Patta | D14: kg | E14: Spices | F14: 0.5 | G14: 600 | H14: 580 | I14: 580
B15: 11 | C15: Jeera | D15: kg | E15: Spices | F15: 0.5 | G15: 500 | H15: 480 | I15: 480
B16: 12 | C16: Akha Masala | D16: kg | E16: Spices | F16: 0.5 | G16: 500 | H16: 480 | I16: 480
B17: 13 | C17: Dal Toor | D17: kg | E17: Pulses | F17: 20 | G17: 120 | H17: 115 | I17: 115
B18: 14 | C18: Lehsun | D18: kg | E18: Vegetables | F18: 2 | G18: 80 | H18: 75 | I18: 75 | J18: Local Market
B19: 15 | C19: FISH | D19: kg | E19: Meat | F19: 5 | G19: 300 | H19: 290 | I19: 290 | J19: Fresh Meats
B20: 16 | C20: Sukha Mirch | D20: kg | E20: Spices | F20: 1 | G20: 300 | H20: 290 | I20: 290
B21: 17 | C21: Rice | D21: kg | E21: Grains | F21: 50 | G21: 45 | H21: 43 | I21: 43 | J21: Rajesh Grains
B22: 18 | C22: Dhania P | D22: kg | E22: Spices | F22: 0.5 | G22: 350 | H22: 340 | I22: 340
B23: 19 | C23: Rai | D23: kg | E23: Spices | F23: 0.5 | G23: 300 | H23: 290 | I23: 290
B24: 20 | C24: Garam Masala | D24: kg | E24: Spices | F24: 0.5 | G24: 450 | H24: 430 | I24: 430
B25: 21 | C25: Oil | D25: litre | E25: Oil | F25: 15 | G25: 150 | H25: 145 | I25: 145
B26: 22 | C26: Tomato | D26: kg | E26: Vegetables | F26: 10 | G26: 30 | H26: 32 | I26: 32 | J26: Local Market
B27: 23 | C27: CHICKEN | D27: kg | E27: Meat | F27: 10 | G27: 240 | H27: 235 | I27: 235 | J27: Fresh Meats
B28: 24 | C28: Atta | D28: kg | E28: Grains | F28: 30 | G28: 35 | H28: 34 | I28: 34 | J28: Rajesh Grains

Sheet Recipe
B2: RCS Canteen — Recipe Master
B4: No | C4: Recipe Name | D4: Description | E4: Meal Type | F4: Base Servings | G4: Instructions
B5: 1 | C5: Chicken Curry | D5: Spicy chicken curry lunch | E5: Lunch | F5: 100
B6: 2 | C6: Dal Rice | D6: Classic dal rice lunch | E6: Lunch | F6: 100

Sheet Recipe Ingredient
B2: RCS Canteen — Recipe Ingredients
B4: No | C4: Recipe | D4: Ingredient | E4: Quantity | F4: Unit
B5: 1 | C5: Dal Rice | D5: Rice | E5: 15 | F5: kg
B6: 2 | C6: Chicken Curry | D6: Oil | E6: 2 | F6: litre
B7: 3 | C7: Dal Rice | D7: Dal Toor | E7: 8 | F7: kg
B8: 4 | C8: Chicken Curry | D8: Lehsun | E8: 0.5 | F8: kg
B9: 5 | C9: Dal Rice | D9: Salt | E9: 0.3 | F9: kg
B10: 6 | C10: Chicken Curry | D10: Adrak | E10: 0.5 | F10: kg
B11: 7 | C11: Chicken Curry | D11: Tomato | E11: 5 | F11: kg
B12: 8 | C12: Dal Rice | D12: Mirch-P | E12: 0.1 | F12: kg
B13: 9 | C13: Chicken Curry | D13: Mirch-P | E13: 0.2 | F13: kg
B14: 10 | C14: Chicken Curry | D14: Haldi-P | E14: 0.1 | F14: kg
B15: 11 | C15: Chicken Curry | D15: Onion | E15: 5 | F15: kg
B16: 12 | C16: Chicken Curry | D16: Garam Masala | E16: 0.1 | F16: kg
... B18: 14 | C18: Chicken Curry | D18: CHICKEN | E18: 15 | F18: kg

Sheet Budget
B2: RCS Canteen — Budget
B4: No | C4: Month | D4: Food Budget | E4: Operating Budget | F4: Total Budget | G4: Alert Threshold (%)
B5: 1 | C5: 2026-08 | D5: 500000 | E5: 750000 | F5: 750000 | G5: 80

Sheet Expense
B2: RCS Canteen — Expenses
B4: No | C4: Date | D4: Category | E4: Description | F4: Amount | G4: Payment Method | H4: Approved By | I4: Notes

Sheet Daily Meal Served
B2: RCS Canteen — Daily Meals Served
B4: No | C4: Date | D4: Meal Type | E4: Count | F4: Notes

Sheet Stock Movement
B2: RCS Canteen — Stock Movement Log
B4: No | C4: Date | D4: Ingredient | E4: Movement Type | F4: Quantity | G4: Unit | H4: Reference | I4: Notes

Sheet Audit Log
B2: RCS Canteen — Audit Log
B4: No | C4: Date | D4: User | E4: Role | F4: Action | G4: Entity Type | H4: Entity Name | I4: Description
B5: 1 | C5: 2026-08-03T09:48:05+05:30 | D5: System | F5: CREATE | G5: Budget | H5: 2026-08 | I5: Created budget for 2026-08
B6: 2 | C6: 2026-08-03T09:47:13+05:30 | D6: System | F6: SEED | G6: System | I6: Database seeded with sample data

Sheet User
B2: RCS Canteen — Users
B4: No | C4: Name | D4: Email | E4: Role
B5: 1 | C5: Admin User | D5: admin@rcs-canteen.com | E5: admin
